Workbook
Name AdditionalOtherIncome: Inputs!$B$49
Name Address: Inputs!$B$10
Name AssetManagementFeeOfEgi: Inputs!$B$28
Name BadDebt: Inputs!$B$24
Name CommonExteriorCapex: Inputs!$B$35
Name ExitCapRate: Inputs!$B$18
Name ExpenseGrowth: Inputs!$B$22
Name HoldPeriodYears: Inputs!$B$17
Name IncomeGrowth: Inputs!$B$21
Name InteriorRenovationCostUnit: Inputs!$B$34
Name IrrTarget: Inputs!$B$47
Name LoanInterestRate: Inputs!$B$16
Name Ltv: Inputs!$B$15
Name ManagementFeeOfEgi: Inputs!$B$27
Name MiscellaneousExpenseAnnual: Inputs!$B$37
Name OtherRentalDeduction: Inputs!$B$29
Name PremiumPerUnit: Inputs!$B$31
Name PriceOverride: Inputs!$B$6
Name PropertyName: Inputs!$B$9
Name PurchaseCapRate: Inputs!$B$14
Name RentRoll_FirstDataRow: 'Rent Roll'!$A$23
Name RR_AsOf: 'Rent Roll'!$B$6
Name RR_OfficialOccupancy: 'Rent Roll'!$B$10
Name RR_OfficialOccupied: 'Rent Roll'!$B$8
Name RR_OfficialUnits: 'Rent Roll'!$B$7
Name RR_OfficialVacant: 'Rent Roll'!$B$9
Name SiteAcres: Inputs!$B$12
Name StabilizedOccupancyTarget: Inputs!$B$26
Name T12_Controllable: 'T12 Actuals'!$B$16
Name T12_EGI: 'T12 Actuals'!$B$10
Name T12_GPR: 'T12 Actuals'!$B$6
Name T12_Insurance: 'T12 Actuals'!$B$19
Name T12_NOI: 'T12 Actuals'!$B$23
Name T12_OpEx: 'T12 Actuals'!$B$22
Name T12_OtherIncome: 'T12 Actuals'!$B$9
Name T12_RawFirstRow: 'T12 Actuals'!$A$30
Name T12_Taxes: 'T12 Actuals'!$B$20
Name T12_Utilities: 'T12 Actuals'!$B$17
Name Tax_Millage: Tax!$B$9
Name Tax_NonAdValorem: Tax!$B$10
Name Tax_PIN: Tax!$B$6
Name Tax_TaxableValue: Tax!$B$8
Name TaxGrowth: Inputs!$B$23
Name UnitMix_FirstDataRow: 'Unit Mix'!$A$6
Name Units: Inputs!$B$13
Name UnitsRenovatedPerMonth: Inputs!$B$45
Name ValueAddUnits: Inputs!$B$30
Name YearBuilt: Inputs!$B$11
Name Tax_ReassessPct: Tax!$B$19

Sheet Dashboard
A1: =UPPER(Inputs!$B$9) -> RIVERBEND APARTMENTS
A2: =Inputs!$B$10&" | "&TEXT(Inputs!$B$13,"#,##0")&"-Unit Value-Add | Built "&Inputs!$B$11&" | "&TEXT(Inputs!$B$12,"0.00")&" Acres" -> 4100 Millrace Pointe Drive, Dayton, OH 45415 | 96-Unit Value-Add | Built 1987 | 7.40 Acres
A4: =Inputs!$B$13 -> 96 | B4: =Inputs!$B$11 -> 1987 | C4: =TEXT('Unit Mix'!$B$2,"#,##0")&" SF" -> 898 SF | D4: ='Rent Roll'!$B$10 -> 0.9375 | E4: =IFERROR('Rent Roll'!$B$19/Inputs!$B$13,0) -> 1089.5833 | F4: ='Rent Comps'!$L$12 -> 0.938
A5: UNITS | B5: YEAR BUILT | C5: AVG UNIT SIZE | D5: OCCUPANCY | E5: AVG RENT (IN-PLACE) | F5: MARKET OCC (OM COMPS)
A7: ='Debt & Exit'!$B$6 -> 8442177.4 | B7: =IFERROR('Debt & Exit'!$B$7,0) -> 87939.348 | C7: ='T12 Actuals'!$B$23 -> 523415 | D7: =IFERROR('Pro Forma'!$D$30,0) -> 484834.88 | E7: =Inputs!$B$36 -> 883600 | F7: ='Max Price Solver'!$B$42 -> 8912387.4
A8: PURCHASE PRICE | B8: PRICE PER DOOR | C8: T12 NOI | D8: YEAR 1 NOI | E8: TOTAL CAPEX | F8: MAX PRICE @ 16% IRR
A10: =IF(AND('Debt & Exit'!$B$25=0,'Debt & Exit'!$B$26<>1),"n/a",'Debt & Exit'!$B$25) -> 0.19043256 | B10: =IFERROR('Debt & Exit'!$B$26,0) -> 2.2099212 | C10: =IFERROR('Exit Scenarios'!$C$16,0) -> 0.10061883 | D10: =IFERROR('Pro Forma'!$D$30/'Debt & Exit'!$C$21,0) -> 1.4916903 | E10: =Inputs!$B$30*Inputs!$B$31*12 -> 146880 | F10: =Tax!$B$16-Tax!$B$12 -> 18482.996
A11: ="LEVERED IRR (SALE YR"&Inputs!$B$17&")" -> LEVERED IRR (SALE YR5) | B11: EQUITY MULTIPLE | C11: YR2 CASH-ON-CASH | D11: YEAR 1 DSCR | E11: NOI UPSIDE / YR | F11: TAX INCREASE / YR
A13: DETAILS - HOW EACH NUMBER IS BUILT
A14: Metric | B14: Value | C14: How calculated
A15: Units | B15: =Inputs!$B$13 -> 96 | C15: Linked to Inputs.
A16: T12 NOI | B16: ='T12 Actuals'!$B$23 -> 523415 | C16: Actual trailing-12 NOI.
A17: Purchase Price | B17: ='Debt & Exit'!$B$6 -> 8442177.4 | C17: T12 NOI / purchase cap rate, unless an override price is entered on Inputs.
A18: Price Per Unit | B18: =IFERROR('Debt & Exit'!$B$7,0) -> 87939.348 | C18: Purchase price / total units.
A19: Loan Amount | B19: ='Debt & Exit'!$B$8 -> 5909524.2 | C19: Purchase price x LTV.
A20: Initial Equity Required | B20: ='Debt & Exit'!$B$12 -> 3669518.5 | C20: Price + capex + closing - loan.
A21: Year 1 NOI | B21: =IFERROR('Pro Forma'!$D$30,0) -> 484834.88 | C21: In-place rent + partial loss-to-lease + reno premium net of downtime, less normalized expenses and reset taxes. Capex is NOT in NOI.
A22: Year 5 NOI | B22: ='Pro Forma'!$H$30 -> 771593.37 | C22: Full reno premium + income growth, less reset taxes.
A23: Year 8 NOI | B23: ='Pro Forma'!$K$30 -> 843140.9 | C23: Year 8 of the extended pro forma - drives the Year 8 exits.
A24: Year 1 DSCR | B24: =IFERROR('Pro Forma'!$D$30/'Debt & Exit'!$C$21,0) -> 1.4916903 | C24: Year 1 NOI / annual debt service.
A25: Levered IRR (hold-period sale) | B25: ='Debt & Exit'!$B$25 -> 0.19043256 | C25: Full equity cash flows through the Inputs hold period, incl. net sale proceeds.
A26: Equity Multiple | B26: =IFERROR('Debt & Exit'!$B$26,0) -> 2.2099212 | C26: Total distributions / initial equity.
A27: Current County Tax | B27: =Tax!$B$12 -> 165393 | C27: Taxable value x millage + non-ad valorem.
A28: New Tax After Sale | B28: =Tax!$B$16 -> 183876 | C28: Purchase price x millage + non-ad valorem (FL reassessment).
A29: Official Rent Roll Occupancy | B29: ='Rent Roll'!$B$10 -> 0.9375 | C29: From rent roll report summary.
A30: Current Avg Rent / Unit | B30: =IFERROR('Rent Roll'!$B$19/Inputs!$B$13,0) -> 1089.5833 | C30: In-place charges with vacant units counted at market rent, / total units.
A31: Target Avg Rent Post-Reno | B31: =IFERROR(('Rent Roll'!$B$16+Inputs!$B$30*Inputs!$B$31)/Inputs!$B$13,0) -> 1150.2604 | C31: Current in-place + value-add units x monthly premium, / total units.
A32: Market Avg Occupancy (OM comp set) | B32: ='Rent Comps'!$L$12 -> 0.938 | C32: Average of the comp set occupancy - compare to subject for occupancy upside.
A33: Units to Renovate | B33: =Inputs!$B$30 -> 72 | C33: Value-add units from Inputs.
A34: Total NOI Opportunity | B34: =Inputs!$B$30*Inputs!$B$31*12 -> 146880 | C34: Value-add units x monthly premium x 12, before downtime.
A35: Max Price to Hit IRR Target | B35: ='Max Price Solver'!$B$42 -> 8912387.4 | C35: Interpolated on the Max Price Solver tab, selling in the hold-period year.
A36: ...same, per unit | B36: ='Max Price Solver'!$B$43 -> 92837.369 | C36: Solved max price / total units.
A38: RETURNS vs TARGETS (detail on Exit Scenarios tab)
A39: Scenario | B39: IRR | C39: Equity Multiple | D39: IRR Target | E39: Status
A40: Sale Year 3 | B40: ='Exit Scenarios'!B14 -> 0.22213197 | C40: =IFERROR('Exit Scenarios'!B15,0) -> 1.7815366 | D40: =Inputs!$B$47 -> 0.16 | E40: ='Exit Scenarios'!$C$48 -> PASS
A41: Sale Year 5 | B41: ='Exit Scenarios'!C14 -> 0.19043256 | C41: =IFERROR('Exit Scenarios'!C15,0) -> 2.2099212 | D41: =Inputs!$B$47 -> 0.16 | E41: ='Exit Scenarios'!$C$49 -> PASS
A42: Sale Year 8 | B42: ='Exit Scenarios'!D14 -> 0.17158252 | C42: =IFERROR('Exit Scenarios'!D15,0) -> 2.9223389 | D42: =Inputs!$B$47 -> 0.16 | E42: ='Exit Scenarios'!$C$50 -> PASS
A43: Refi Yr3 + Sale Yr5 | B43: ='Exit Scenarios'!E14 -> 0.21428408 | C43: =IFERROR('Exit Scenarios'!E15,0) -> 2.1095883 | D43: =Inputs!$B$47 -> 0.16 | E43: ='Exit Scenarios'!$C$51 -> PASS
A44: Refi Yr3 + Sale Yr8 | B44: ='Exit Scenarios'!F14 -> 0.20717234 | C44: =IFERROR('Exit Scenarios'!F15,0) -> 2.7064833 | D44: =Inputs!$B$47 -> 0.16 | E44: ='Exit Scenarios'!$C$52 -> PASS
A45: Refi Yr5 + Sale Yr8 | B45: ='Exit Scenarios'!G14 -> 0.19016913 | C45: =IFERROR('Exit Scenarios'!G15,0) -> 2.7588606 | D45: =Inputs!$B$47 -> 0.16 | E45: ='Exit Scenarios'!$C$53 -> PASS
...

Sheet Inputs
A1: =Inputs!$B$9&" - Underwriting Inputs" -> Riverbend Apartments - Underwriting Inputs
A2: =B14 -> 0.062 | B2: =B15 -> 0.7 | C2: =B17 -> 5 | D2: =B47 -> 0.16 | E2: =IF(B6>0,B6,"Off (cap rate)") -> Off (cap rate) | F2: =B45 -> 6
A3: PURCHASE CAP RATE | B3: LTV | C3: HOLD PERIOD (YRS) | D3: IRR TARGET | E3: PRICE OVERRIDE | F3: UNITS RENOVATED/MO
A5: Input / Assumption | B5: Value | C5: Where it comes from (gold box = you can change it, sage = read from your documents)
A6: Purchase Price Override ($, 0 = T12 NOI / cap rate) | B6: 0 | C6: If > 0, this price replaces the cap-rate-derived purchase price everywhere: loan, equity, tax reset, returns, scenarios.
A7: Cap-Rate-Derived Price (reference) | B7: ='T12 Actuals'!$B$23/B14 -> 8442177.4 | C7: What the purchase price would be with the override off. To revert, clear the override above back to 0.
A8: Active Purchase Price (in use now) | B8: ='Debt & Exit'!$B$6 -> 8442177.4 | C8: Whichever of the two above is actually driving the model right now.
A9: Property Name | B9: Riverbend Apartments | C9: OM / county record. Text label only.
A10: Address | B10: 4100 Millrace Pointe Drive, Dayton, OH 45415 | C10: OM / public record. Text label only.
A11: Year Built | B11: 1987 | C11: OM / county record. Shown on Dashboard fast facts.
A12: Site Acres | B12: 7.4 | C12: OM / county record. Shown on Dashboard banner.
A13: Units | B13: 96 | C13: OM and rent roll. Used for price per door and per-unit checks.
A14: Purchase Cap Rate | B14: 0.062 | C14: Purchase price = T12 NOI / purchase cap rate.
A15: LTV | B15: 0.7 | C15: Debt = purchase price x LTV.
A16: Loan Interest Rate | B16: 0.055 | C16: Placeholder - source needed. Interest-only debt service = loan amount x rate.
A17: Hold Period (years) | B17: 5 | C17: Modeling assumption. THE hold-period switch: the model runs eight years and the sale lands in this year on Debt & Exit, the Dashboard, and the Max Price Solver. 1-8.
A18: Exit Cap Rate | B18: 0.06 | C18: Modeling assumption - source needed. Exit value = the hold-period year's NOI / exit cap rate.
A19: Disposition / Closing Cost at Exit | B19: 0.05 | C19: Prior 5% convention. Subtracted from exit sale proceeds only.
A20: Closing Cost | B20: 0.03 | C20: Closing cost = purchase price x 3%. Applies to acquisition/equity and return tabs.
A21: Income Growth | B21: 0.03 | C21: Income grows 3% YoY after value-add bump, Years 2-8.
A22: Expense Growth | B22: 0.03 | C22: Non-tax operating expenses grow 3% YoY, Years 2-8.
... A24: Bad Debt % | B24: 0.02 | C24: Bad debt = adjusted gross potential rent x 2%.
A25: Vacancy % | B25: =1-'Rent Roll'!$B$10 -> 0.0625 | C25: Calculated from rent roll. Vacancy % = 1 - official rent-roll occupancy.
A26: Stabilized Occupancy Target % | B26: 0.96
A27: Management Fee % of EGI | B27: 0.03 | C27: Management fee = EGI x 3%.
A28: Asset Management Fee % of EGI | B28: 0.02 | C28: Asset management fee = EGI x 2%.
A29: Concessions (annual $) | B29: =B13*B50*B51*'Rent Roll'!$B$2 -> 17433.333 | C29: Concessions = units x share turning x months of rent x avg rent/unit (factors below). Grown with income growth in the pro forma.
A30: Value-Add Units | B30: 72 | C30: OM value-add plan. Used in renovation premium calculation.
A31: Value-Add Premium / Unit / Month | B31: 170 | C31: OM value-add plan. Monthly premium = online renovated units x $255.
A32: Renovation Downtime (months of rent lost per renovated unit) | B32: 1 | C32: Single downtime input: each renovated unit loses this many months of rent (renovations happen at lease turnover). Also drives the units-under-renovation schedule column on Reno Pace.
A33: Renovation Online Start Month | B33: 3 | C33: First completed/online batch starts in month 3; monthly pace continues thereafter.
A34: Interior Renovation Cost / Unit | B34: 8800 | C34: Prior model / needs confirmation. Interior capex = units x cost per unit.
A35: Common / Exterior Capex | B35: 250000 | C35: Prior model / needs confirmation. Added to total capex.
A36: Total Capex | B36: =B30*B34+B35 -> 883600 | C36: Calculated by model. Total capex = value-add units x interior cost/unit + common/exterior capex.
A37: Miscellaneous Expense (One-Time, Year 1 Only) | B37: 10000 | C37: One-time expense charged in Year 1 only. Does not recur or grow in Years 2-8.
A39: ADDED - SCENARIOS, PHASING & DEBT STRUCTURE
A40: Refi Cap Rate | B40: 0.0595 | C40: Modeling assumption. Refi value = the refi year's NOI / this cap. Exit Scenarios models a Year 3 and a Year 5 refinance.
A41: Refi LTV | B41: 0.7 | C41: New loan = refi value x this LTV.
A42: Refi Closing Cost % | B42: 0.01 | C42: Modeling assumption. Cost = new loan x this %.
A43: Refi Interest Rate | B43: 0.0545 | C43: Placeholder - needs quote. New debt service after refi, on both the Year 3 and Year 5 refi cases.
...

Sheet T12 Actuals
A1: T12 Actuals - Summary
A2: =B23 -> 523415 | B2: =B10 -> 1231000 | C2: =B22 -> 707585 | D2: =IFERROR(B23/B10,0) -> 0.42519496
A3: T12 NOI | B3: T12 EGI | C3: TOTAL OPEX | D3: NOI MARGIN
A4: Summary of the uploaded T12. Raw monthly account detail is pasted below.
A5: Line | B5: T12 Amount | C5: Notes
A6: Gross Potential Rent | B6: 1305600 | C6: Starting point only. Source T12 number. Year 1 underwrite uses rent roll market rent instead.
A7: Less: vacancy, concessions, bad debt | B7: -166500 | C7: Used to understand actual drag. Company underwrite normalizes key items instead of blindly using this total.
A8: Net Rental Income | B8: 1139100 | C8: Reference point. Source T12 number.
A9: Other Income | B9: 91900 | C9: Pro forma starts here. Year 1 grows this by 3%.
A10: Effective Gross Income (EGI) | B10: 1231000 | C10: Fee base / margin check. Used as actual T12 benchmark.
A11: Repairs & Maintenance | B11: 70700 | C11: Total Repairs and Maintenance section of the RM T12.
A12: Turnover Costs | B12: 26600 | C12: Total Turnover Costs section of the RM T12.
A13: Labor Costs (Payroll) | B13: 123000 | C13: Total Labor Costs section of the RM T12.
A14: Advertising & Promotions | B14: 15800 | C14: Total Advertising and Promotions section of the RM T12.
A15: General & Administrative | B15: 27700 | C15: Total General and Administrative Costs section of the RM T12.
A16: Controllable Expenses | B16: 263800 | C16: Sum of the five sections above. Pro forma expense base — each section grows 3%/yr (or uses its benchmark).
A17: Utilities | B17: 121500 | C17: Pro forma expense base. Year 1 grows by 3%.
... A26: Actual Concessions - net | B26: -11800 | C26: Used as a deduction ratio. Converted to % of GPR for underwriting.
A28: Raw monthly account detail below - use this only if you need to trace the T12 summary back to individual account lines.
A29: Source Row | B29: Account | C29: Label | D29: Oct 2025 | E29: Nov 2025 | F29: Dec 2025 | G29: Jan 2026 | H29: Feb 2026 | I29: Mar 2026 | J29: Apr 2026 | K29: May 2026 | L29: Jun 2026 | M29: Jul 2026 | N29: Aug 2026 | O29: Sep 2026 | P29: Total | Q29: Category
A30: 7 | C30: INCOME | P30: =SUM(D30:O30) -> 0
A31: 8 | C31: Rental Income | P31: =SUM(D31:O31) -> 0
A32: 9 | B32: 4000-00 | C32: Gross Potential Rent | D32: 105210 | E32: 105862 | F32: 106515 | G32: 107168 | H32: 107821 | I32: 108474 | J32: 109126 | K32: 109779 | L32: 110432 | M32: 111085 | N32: 111738 | O32: 112390 | P32: =SUM(D32:O32) -> 1305600
A33: 10 | C33: Total Gross Potential Rent | D33: 105210 | E33: 105862 | F33: 106515 | G33: 107168 | H33: 107821 | I33: 108474 | J33: 109126 | K33: 109779 | L33: 110432 | M33: 111085 | N33: 111738 | O33: 112390 | P33: =SUM(D33:O33) -> 1305600
A34: 11 | B34: 4510-00 | C34: Vacancy Loss | D34: -7090 | E34: -6109 | F34: -6828 | G34: -6246 | H34: -7784 | I34: -6308 | J34: -7052 | K34: -7921 | L34: -7122 | M34: -8087 | N34: -6093 | O34: -8260 | P34: =SUM(D34:O34) -> -84900
A35: 12 | B35: 4510-01 | C35: Vacancy - Model/Down Units | D35: 0 | E35: 0 | F35: 0 | G35: 0 | H35: 0 | I35: 0 | J35: 0 | K35: 0 | L35: 0 | M35: 0 | N35: 0 | O35: 0 | P35: =SUM(D35:O35) -> 0
A36: 13 | B36: 4520-00 | C36: Loss to Lease | D36: -4722 | E36: -4711 | F36: -4569 | G36: -4675 | H36: -4900 | I36: -5024 | J36: -4981 | K36: -4797 | L36: -4697 | M36: -4728 | N36: -5028 | O36: -4568 | P36: =SUM(D36:O36) -> -57400
A37: 14 | B37: 4530-00 | C37: Concessions | D37: -830 | E37: -1002 | F37: -929 | G37: -646 | H37: -879 | I37: -953 | J37: -709 | K37: -824 | L37: -1250 | M37: -1497 | N37: -1258 | O37: -1023 | P37: =SUM(D37:O37) -> -11800
A38: 15 | B38: 4535-00 | C38: Concessions - Other | D38: 0 | E38: 0 | F38: 0 | G38: 0 | H38: 0 | I38: 0 | J38: 0 | K38: 0 | L38: 0 | M38: 0 | N38: 0 | O38: 0 | P38: =SUM(D38:O38) -> 0
A39: 16 | B39: 4540-00 | C39: Bad Debt Write-offs | D39: -1455 | E39: -986 | F39: -1103 | G39: -1411 | H39: -1007 | I39: -1220 | J39: -951 | K39: -1239 | L39: -1964 | M39: -2006 | N39: -996 | O39: -962 | P39: =SUM(D39:O39) -> -15300
A40: 17 | B40: 4545-00 | C40: Bad Debt Recovery | D40: 316 | E40: 316 | F40: 339 | G40: 160 | H40: 219 | I40: 187 | J40: 182 | K40: 264 | L40: 255 | M40: 260 | N40: 138 | O40: 264 | P40: =SUM(D40:O40) -> 2900
A41: 18 | C41: Total Deductions | D41: -13781 | E41: -12492 | F41: -13090 | G41: -12818 | H41: -14351 | I41: -13318 | J41: -13511 | K41: -14517 | L41: -14778 | M41: -16058 | N41: -13237 | O41: -14549 | P41: =SUM(D41:O41) -> -166500
A42: 19 | C42: Net Rental Income | D42: 91429 | E42: 93370 | F42: 93425 | G42: 94350 | H42: 93470 | I42: 95156 | J42: 95615 | K42: 95262 | L42: 95654 | M42: 95027 | N42: 98501 | O42: 97841 | P42: =SUM(D42:O42) -> 1139100
A43: 20 | C43: Other Income | P43: =SUM(D43:O43) -> 0
A44: 21 | B44: 4700-00 | C44: Utility Reimbursement (RUBS) | D44: 3744 | E44: 3824 | F44: 3835 | G44: 3744 | H44: 3755 | I44: 4744 | J44: 4801 | K44: 4496 | L44: 4645 | M44: 4576 | N44: 3861 | O44: 3775 | P44: =SUM(D44:O44) -> 49800
A45: 22 | B45: 4710-00 | C45: Late Fees | D45: 709 | E45: 749 | F45: 909 | G45: 658 | H45: 801 | I45: 736 | J45: 646 | K45: 760 | L45: 892 | M45: 915 | N45: 877 | O45: 648 | P45: =SUM(D45:O45) -> 9300
A46: 23 | B46: 4720-00 | C46: Application and Admin Fees | D46: 564 | E46: 582 | F46: 547 | G46: 558 | H46: 608 | I46: 568 | J46: 465 | K46: 583 | L46: 577 | M46: 787 | N46: 611 | O46: 450 | P46: =SUM(D46:O46) -> 6900
A47: 24 | B47: 4730-00 | C47: Pet Rent and Fees | D47: 1077 | E47: 1107 | F47: 1055 | G47: 1097 | H47: 1132 | I47: 1056 | J47: 1030 | K47: 1174 | L47: 1164 | M47: 1154 | N47: 1061 | O47: 1093 | P47: =SUM(D47:O47) -> 13200
A48: 25 | B48: 4740-00 | C48: Laundry and Vending | D48: 349 | E48: 323 | F48: 319 | G48: 331 | H48: 330 | I48: 342 | J48: 373 | K48: 338 | L48: 317 | M48: 362 | N48: 372 | O48: 344 | P48: =SUM(D48:O48) -> 4100
A49: 26 | B49: 4750-00 | C49: Parking, Storage and Other | D49: 809 | E49: 732 | F49: 702 | G49: 727 | H49: 831 | I49: 674 | J49: 650 | K49: 633 | L49: 686 | M49: 713 | N49: 643 | O49: 800 | P49: =SUM(D49:O49) -> 8600
...

Sheet Rent Roll
A1: Rent Roll - Source, Parsed Audit, and Unit Detail
A2: =B10 -> 0.9375 | B2: =IFERROR(B19/Inputs!$B$13,0) -> 1089.5833 | C2: =B9 -> 6 | D2: =B17 -> 10950
A3: OFFICIAL OCCUPANCY | B3: ADJ AVG RENT/UNIT | C3: VACANT UNITS | D3: LOSS-TO-LEASE (MO)
A5: Metric | B5: Value | C5: Source | D5: How/Why | E5: Flag | F5: Note
A6: Report As Of | B6: 46310 | C6: Rent roll source | D6: Report date from uploaded rent roll. | E6: Source
A7: Official Units | B7: 96 | C7: Rent roll summary / OM | D7: Source unit count. | E7: Source
A8: Official Occupied Units | B8: 90 | C8: Rent roll report summary | D8: Source occupied count from report summary. | E8: Source
A9: Official Vacant Units | B9: 6 | C9: Rent roll report summary | D9: Source vacant count from report summary. | E9: Source
A10: Official Occupancy | B10: 0.9375 | C10: Rent roll report summary | D10: Official occupancy % from rent roll summary. | E10: Source
A11: Parsed Unit Count | B11: =COUNTA(A23:A2022) -> 96 | C11: Calculated from unit-level rows | D11: COUNTA of unit numbers in the parsed unit table. | E11: Calculated | F11: Audit ties to source unit count.
A12: Parsed Occupied Units | B12: =SUM(M23:M2022) -> 90 | C12: Calculated from rent charge flag | D12: SUM of occupied flags where rent charge is present. | E12: Calculated | F12: Parser count can differ from official summary.
A13: Parsed Vacant Units | B13: =B11-B12 -> 6 | C13: Calculated from unit-level rows | D13: Parsed unit count minus parsed occupied units. | E13: Calculated | F13: Audit item.
A14: Parsed Occupancy | B14: =IFERROR(B12/B11,0) -> 0.9375 | C14: Calculated from unit-level rows | D14: Parsed occupied units / parsed unit count. | E14: Calculated | F14: Compare to official occupancy.
A15: Monthly Market Rent | B15: =SUM(F23:F2022) -> 109135 | C15: Calculated from unit-level rows | D15: SUM of market rent column. | E15: Calculated | F15: Annualizes into Year 1 base GPR.
A16: Monthly In-place Rent Charges | B16: =SUM(G23:G2022) -> 98185 | C16: Calculated from unit-level rows | D16: SUM of rent charge column. | E16: Calculated | F16: Shows actual rent roll charge base.
A17: Monthly Loss-to-Lease | B17: =B15-B16 -> 10950 | C17: Calculated from unit-level rows | D17: Monthly market rent minus rent charges. | E17: Calculated | F17: Shows embedded rent gap before renovations.
A18: Total Resident Balance | B18: =SUM(L23:L2022) -> 3760 | C18: Calculated from unit-level rows | D18: SUM of balance column. | E18: Calculated | F18: Collections / bad debt diligence item.
A19: Adjusted Monthly Rent (vacants at market) | B19: =B16+SUMPRODUCT((G23:G2022=0)*(F23:F2022)) -> 104600 | C19: Calculated from unit-level rows | D19: In-place rent charges plus market rent for vacant units, so $0 vacant charges do not drag the average down. | E19: Calculated
A22: Unit | B22: Unit Type | C22: SqFt | D22: Resident ID | E22: Resident Name | F22: Market Rent | G22: Rent Charge | H22: Total Charges | I22: Move In | J22: Lease Expiration | K22: Move Out | L22: Balance | M22: Occupied Flag | N22: Loss to Lease | O22: Status Section
A23: A101 | B23: A1 | C23: 720 | D23: R100200 | E23: Mbeki, Imani | F23: 965 | G23: 915 | H23: 915 | I23: 46060 | J23: 46424 | L23: 0 | M23: 1 | N23: 117 | O23: Current/Notice/Vacant Residents
A24: A102 | B24: B2 | C24: 1032 | D24: R100207 | E24: Yoder, Devon | F24: 1235 | G24: 1135 | H24: 1135 | I24: 46099 | J24: 46463 | L24: 0 | M24: 1 | N24: 158 | O24: Current/Notice/Vacant Residents
A25: A103 | B25: B1 | C25: 932 | D25: R100214 | E25: Lindqvist, Aaliyah | F25: 1160 | G25: 1090 | H25: 1090 | I25: 45682 | J25: 46411 | L25: 0 | M25: 1 | N25: -22 | O25: Current/Notice/Vacant Residents
A26: A104 | B26: B1 | C26: 918 | D26: R100221 | E26: Sandoval, Elena | F26: 1150 | G26: 1105 | H26: 1105 | I26: 46049 | J26: 46413 | L26: 0 | M26: 1 | N26: 87 | O26: Current/Notice/Vacant Residents
A27: A201 | B27: A1 | C27: 712 | D27: R100228 | E27: Brennan, Marcus | F27: 985 | G27: 955 | H27: 955 | I27: 45329 | J27: 46423 | L27: 0 | M27: 1 | N27: 208 | O27: Current/Notice/Vacant Residents
A28: A202 | B28: B1 | C28: 924 | D28: R100235 | E28: Espinoza, Andre | F28: 1150 | G28: 1090 | H28: 1090 | I28: 46134 | J28: 46498 | L28: 0 | M28: 1 | N28: -33 | O28: Current/Notice/Vacant Residents
A29: A203 | B29: B1 | C29: 924 | D29: R100242 | E29: Quill, Priya | F29: 1140 | G29: 1070 | H29: 1070 | I29: 45994 | J29: 46358 | L29: 0 | M29: 1 | N29: 86 | O29: Current/Notice/Vacant Residents
A30: A204 | B30: B2 | C30: 1046 | D30: R100249 | E30: Dunmore, Tyrone | F30: 1250 | G30: 1200 | H30: 1200 | I30: 45560 | J30: 46654 | L30: 0 | M30: 1 | N30: -21 | O30: Current/Notice/Vacant Residents
A31: A301 | B31: B1 | C31: 924 | D31: R100256 | E31: Espinoza, Rosa | F31: 1160 | G31: 1160 | H31: 1160 | I31: 45540 | J31: 46634 | L31: 75 | M31: 1 | N31: -55 | O31: Current/Notice/Vacant Residents
A32: A302 | B32: A1 | C32: 706 | D32: R100263 | E32: Brennan, Victor | F32: 980 | G32: 950 | H32: 950 | I32: 46046 | J32: 46410 | L32: 0 | M32: 1 | N32: 48 | O32: Current/Notice/Vacant Residents
A33: A303 | B33: B1 | C33: 932 | D33: R100270 | E33: Brennan, Elena | F33: 1160 | G33: 1065 | H33: 1065 | I33: 45468 | J33: 46562 | L33: 0 | M33: 1 | N33: 1699 | O33: Current/Notice/Vacant Residents
A34: A304 | B34: C1 | C34: 1212 | D34: R100277 | E34: Gutierrez, Owen | F34: 1440 | G34: 1410 | H34: 1410 | I34: 46167 | J34: 46531 | L34: 0 | M34: 1 | N34: -77 | O34: Current/Notice/Vacant Residents
... A37: B103 | B37: B1 | C37: 932 | D37: R100298 | E37: Alvarez, Victor | F37: 1150 | G37: 1080 | H37: 1080 | I37: 46126 | J37: 46490 | L37: 0 | M37: 1 | N37: 142 | O37: Current/Notice/Vacant Residents
A38: B104 | B38: A1 | C38: 712 | F38: 975 | G38: 0 | H38: 0 | K38: 46279 | L38: 0 | M38: 0 | N38: 52 | O38: Current/Notice/Vacant Residents
A39: B201 | B39: B1 | C39: 918 | D39: R100312 | E39: Iverson, Hannah | F39: 1150 | G39: 1150 | H39: 1150 | I39: 45973 | J39: 46337 | L39: 320 | M39: 1 | N39: 1674 | O39: Current/Notice/Vacant Residents
A40: B202 | B40: A1 | C40: 712 | D40: R100319 | E40: Castellano, Felix | F40: 975 | G40: 975 | H40: 975 | I40: 45313 | J40: 46407 | L40: 0 | M40: 1 | N40: -77 | O40: Current/Notice/Vacant Residents
A41: B203 | B41: A1 | C41: 720 | D41: R100326 | E41: Mbeki, Luis | F41: 975 | G41: 945 | H41: 945 | I41: 45688 | J41: 46417 | L41: 0 | M41: 1 | N41: -23 | O41: Current/Notice/Vacant Residents
A42: B204 | B42: B1 | C42: 932 | D42: R100333 | E42: Ellison, Sofia | F42: 1155 | G42: 1120 | H42: 1120 | I42: 45382 | J42: 46476 | L42: 0 | M42: 1 | N42: 0 | O42: Current/Notice/Vacant Residents
A43: B301 | B43: A1 | C43: 720 | D43: R100340 | E43: Hawkins, Mei | F43: 965 | G43: 905 | H43: 905 | I43: 45411 | J43: 46505 | L43: 0 | M43: 1 | N43: 25 | O43: Current/Notice/Vacant Residents
A44: B302 | B44: A1 | C44: 712 | D44: R100347 | E44: Kowalski, Marcus | F44: 975 | G44: 975 | H44: 975 | I44: 46091 | J44: 46455 | L44: 0 | M44: 1 | N44: 87 | O44: Current/Notice/Vacant Residents
A45: B303 | B45: C1 | C45: 1204 | D45: R100354 | E45: Lindqvist, Aaliyah | F45: 1450 | G45: 1390 | H45: 1390 | I45: 46007 | J45: 46371 | L45: 0 | M45: 1 | N45: 205 | O45: Current/Notice/Vacant Residents
...

Sheet Unit Mix
A1: Unit Mix - Calculated from Rent Roll Detail
A2: =SUM(B6:B25) -> 96 | B2: =IFERROR(SUMPRODUCT(B6:B25,E6:E25)/SUM(B6:B25),0) -> 898.44583 | C2: =IFERROR(SUMPRODUCT(B6:B25,F6:F25)/SUM(B6:B25),0) -> 1136.8231 | D2: =IFERROR(SUMPRODUCT(B6:B25,G6:G25)/SUM(B6:B25),0) -> 1086.2173
A3: TOTAL UNITS | B3: BLENDED AVG SF | C3: BLENDED MKT RENT | D3: BLENDED IN-PLACE RENT
A5: Unit Type | B5: Units | C5: Occupied | D5: Vacant | E5: Avg SqFt | F5: Avg Market Rent | G5: Avg In-place Rent | H5: Monthly Market Rent | I5: Monthly In-place Rent | J5: How/Why: grouped from unit-level rent roll rows by unit type.
A6: A1 | B6: 36 | C6: 32 | D6: 4 | E6: 713.3 | F6: 975.97 | G6: 936.56 | H6: 35135 | I6: 29970 | J6: Calculated by grouping unit-level rent roll rows by unit type.
A7: B1 | B7: 30 | C7: 30 | D7: 0 | E7: 925 | F7: 1152.67 | G7: 1110.67 | H7: 34580 | I7: 33320 | J7: Calculated by grouping unit-level rent roll rows by unit type.
A8: B2 | B8: 20 | C8: 18 | D8: 2 | E8: 1039.5 | F8: 1245.75 | G8: 1172.78 | H8: 24915 | I8: 21110 | J8: Calculated by grouping unit-level rent roll rows by unit type.
A9: C1 | B9: 10 | C9: 10 | D9: 0 | E9: 1203.2 | F9: 1450.5 | G9: 1378.5 | H9: 14505 | I9: 13785 | J9: Calculated by grouping unit-level rent roll rows by unit type.
J10: Calculated by grouping unit-level rent roll rows; highlights unit-type rent gaps.
J11: Calculated by grouping unit-level rent roll rows; highlights unit-type rent gaps.
J12: Calculated by grouping unit-level rent roll rows; highlights unit-type rent gaps.
J13: Calculated by grouping unit-level rent roll rows; highlights unit-type rent gaps.
J14: Calculated by grouping unit-level rent roll rows; highlights unit-type rent gaps.
J15: Calculated by grouping unit-level rent roll rows; highlights unit-type rent gaps.
J16: Calculated by grouping unit-level rent roll rows; highlights unit-type rent gaps.
J17: Calculated by grouping unit-level rent roll rows; highlights unit-type rent gaps.
J18: Calculated by grouping unit-level rent roll rows; highlights unit-type rent gaps.
J19: Calculated by grouping unit-level rent roll rows; highlights unit-type rent gaps.
J20: Calculated by grouping unit-level rent roll rows; highlights unit-type rent gaps.

Sheet Tax
A1: Property Tax Forecast
A2: =B12 -> 165393 | B2: =B16 -> 183876 | C2: =B16-B12 -> 18482.996 | D2: =B9 -> 23.97
A3: CURRENT TAX | B3: NEW TAX AFTER SALE | C3: ANNUAL INCREASE | D3: MILLAGE RATE
A5: Metric | B5: Value | C5: Notes
A6: County PIN | B6: R72 00811 0006, R72 00811 0007 | C6: County / public tax record. Used to verify parcel.
A7: Site Address | B7: 4100 Millrace Pointe Drive, Dayton, OH 45415 | C7: County / public tax record. Used to confirm subject property.
A8: Current Taxable Value | B8: 6900000 | C8: County tax record / OM tax page. Current county taxable value.
A9: Current Millage Rate | B9: 23.97 | C9: County tax record / OM tax page. Ad valorem tax = taxable value x millage / 1,000 where applicable.
A10: Non-Ad Valorem Tax | B10: 0 | C10: County tax record / OM tax page. Added to ad valorem tax estimate.
A11: Current Ad Valorem Tax Estimate | B11: =IF(OR($B$8<=0,$B$9<=0),$B$13,$B$8*$B$9/1000) -> 165393 | C11: Calculated by model. Taxable value x millage / 1,000.
A12: Current Total Tax Estimate | B12: =IF(OR($B$8<=0,$B$9<=0),$B$13,$B$11+$B$10) -> 165393 | C12: Calculated by model. Ad valorem estimate + non-ad valorem.
A13: T12 Property Tax Expense | B13: 165400 | C13: T12 actuals. Displayed to compare T12 to county/OM tax estimate.
A14: Reassessment Basis After Sale | B14: =$B$8+('Debt & Exit'!$B$6-$B$8)*$B$19 -> 7671088.7 | C14: Calculated by model. Current taxable value plus the share of the step-up to purchase price allowed by the reassessment policy in B19. At 100% this equals the purchase price; at 0% it stays at today's taxable value.
A15: New Ad Valorem Tax After Sale | B15: =IF(OR($B$8<=0,$B$9<=0),$B$13,$B$14*$B$9/1000) -> 183876 | C15: Calculated by model. Reassessment basis x current millage / 1,000.
A16: New Year 1 Total Tax | B16: =IF(OR($B$8<=0,$B$9<=0),$B$13,$B$15+$B$10) -> 183876 | C16: Calculated by model. New ad valorem tax + non-ad valorem tax. With no millage on file it falls back to T12 tax grown one year.
A17: Annual Tax Growth | B17: =Inputs!$B$23 -> 0.03 | C17: Input link. Uses Inputs tax growth assumption.
A18: Tax Rule Note | B18: Reassessment on sale varies by state - set B19 accordingly. Some states reset to market value on a change of ownership (e.g. Florida non-homestead commercial, FS 193.1555): use 100%. Others do not - New Jersey bars reassessing a property solely because it sold (Township of West Milford v. Van Decker), so assessments move only on a district-wide revaluation: use 0% for the base case, or 100% together with the EQUALIZED value and the EFFECTIVE (equalized) millage to model a revaluation landing at market. If taxable value/millage are unavailable, the model uses actual T12 property tax grown by the tax-growth assumption instead of assuming $0. | C18: Confirm the rule for THIS jurisdiction before relying on Year 1 tax. The automated tax lookup writes its finding into B26.
A19: Reassessment on Sale (% of Price) | B19: 0.5 | C19: INPUT. 100% = assessment resets to the purchase price on sale. 0% = no reset; Year 1 tax holds at today's taxable value and only grows by the tax-growth assumption. Drives this tab AND every column of the Max Price Solver.
A21: Tax Forecast | B21: Year 1 | C21: Year 2 | D21: Year 3 | E21: Year 4 | F21: Year 5 | G21: Year 6 | H21: Year 7 | I21: Year 8 | J21: How/Why
A22: Property Tax | B22: =$B$16 -> 183876 | C22: =B22*(1+$B$17) -> 189392.28 | D22: =C22*(1+$B$17) -> 195074.04 | E22: =D22*(1+$B$17) -> 200926.27 | F22: =E22*(1+$B$17) -> 206954.05 | G22: =F22*(1+$B$17) -> 213162.68 | H22: =G22*(1+$B$17) -> 219557.56 | I22: =H22*(1+$B$17) -> 226144.28 | J22: Year 1 applies the reassessment policy in B19 to the purchase price, then grows by tax growth through Year 8. With no taxable value or millage on file it falls back to T12 tax grown forward.
A25: County source URL | B25: https://example.com/demo/montgomery-county-millage
A26: Tax rule/source URL | B26: Ohio re-appraises on a county cycle and a sale alone does not reset the assessment, but a school district can file a complaint citing the sale price; modeled as half the step-up to the purchase price. Values here are the appraised (market) value with the effective rate on it.

Sheet Reno Pace
A1: Renovation Pace - Monthly Ramp with Rent Downtime
A2: =Inputs!$B$30 -> 72 | B2: =Inputs!$B$45 -> 6 | C2: =IFERROR(B33,0) -> 0 | D2: =B38 -> 0
A3: UNITS TO RENOVATE | B3: PACE (UNITS/MO) | C3: YEAR 1 NET IMPACT | D3: STABILIZED PREMIUM/YR
A4: =IF($A$2=0,"No renovation program is modeled: Value-Add Units is 0 on the Inputs tab, so every month below is zero. Enter the number of units to renovate (and the pace) on Inputs to see the schedule.","Units completed monthly starting at the online start month. Renovations happen at lease turnover; each renovated unit is charged the downtime months of lost rent from Inputs.") -> Units completed monthly starting at the online start month. Renovations happen at lease turnover; each renovated unit is charged the downtime months of lost rent from Inputs.
A5: Month | B5: Units Completed This Month | C5: Units Under Renovation | D5: Cumulative Units Online | E5: Monthly Rent Premium | F5: Rent Downtime (downtime months x avg rent) | G5: Net Monthly Impact
A6: 1 | B6: =IF(A6<Inputs!$B$33,0,MAX(0,MIN(Inputs!$B$45,Inputs!$B$30-SUM($B$5:B5)))) -> 0 | C6: =SUMIFS($B$6:$B$101,$A$6:$A$101,">"&A6,$A$6:$A$101,"<="&A6+Inputs!$B$32) -> 0 | D6: =SUM($B$6:B6) -> 0 | E6: =D6*Inputs!$B$31 -> 0 | F6: =IFERROR(B6*('Rent Roll'!$B$16/Inputs!$B$13)*Inputs!$B$32,0) -> 0 | G6: =E6-F6 -> 0
A7: 2 | B7: =IF(A7<Inputs!$B$33,0,MAX(0,MIN(Inputs!$B$45,Inputs!$B$30-SUM($B$5:B6)))) -> 0 | C7: =SUMIFS($B$6:$B$101,$A$6:$A$101,">"&A7,$A$6:$A$101,"<="&A7+Inputs!$B$32) -> 6 | D7: =SUM($B$6:B7) -> 0 | E7: =D7*Inputs!$B$31 -> 0 | F7: =IFERROR(B7*('Rent Roll'!$B$16/Inputs!$B$13)*Inputs!$B$32,0) -> 0 | G7: =E7-F7 -> 0
A8: 3 | B8: =IF(A8<Inputs!$B$33,0,MAX(0,MIN(Inputs!$B$45,Inputs!$B$30-SUM($B$5:B7)))) -> 6 | C8: =SUMIFS($B$6:$B$101,$A$6:$A$101,">"&A8,$A$6:$A$101,"<="&A8+Inputs!$B$32) -> 6 | D8: =SUM($B$6:B8) -> 6 | E8: =D8*Inputs!$B$31 -> 1020 | F8: =IFERROR(B8*('Rent Roll'!$B$16/Inputs!$B$13)*Inputs!$B$32,0) -> 6136.5625 | G8: =E8-F8 -> -5116.5625
A9: 4 | B9: =IF(A9<Inputs!$B$33,0,MAX(0,MIN(Inputs!$B$45,Inputs!$B$30-SUM($B$5:B8)))) -> 6 | C9: =SUMIFS($B$6:$B$101,$A$6:$A$101,">"&A9,$A$6:$A$101,"<="&A9+Inputs!$B$32) -> 6 | D9: =SUM($B$6:B9) -> 12 | E9: =D9*Inputs!$B$31 -> 2040 | F9: =IFERROR(B9*('Rent Roll'!$B$16/Inputs!$B$13)*Inputs!$B$32,0) -> 6136.5625 | G9: =E9-F9 -> -4096.5625
A10: 5 | B10: =IF(A10<Inputs!$B$33,0,MAX(0,MIN(Inputs!$B$45,Inputs!$B$30-SUM($B$5:B9)))) -> 6 | C10: =SUMIFS($B$6:$B$101,$A$6:$A$101,">"&A10,$A$6:$A$101,"<="&A10+Inputs!$B$32) -> 6 | D10: =SUM($B$6:B10) -> 18 | E10: =D10*Inputs!$B$31 -> 3060 | F10: =IFERROR(B10*('Rent Roll'!$B$16/Inputs!$B$13)*Inputs!$B$32,0) -> 6136.5625 | G10: =E10-F10 -> -3076.5625
A11: 6 | B11: =IF(A11<Inputs!$B$33,0,MAX(0,MIN(Inputs!$B$45,Inputs!$B$30-SUM($B$5:B10)))) -> 6 | C11: =SUMIFS($B$6:$B$101,$A$6:$A$101,">"&A11,$A$6:$A$101,"<="&A11+Inputs!$B$32) -> 6 | D11: =SUM($B$6:B11) -> 24 | E11: =D11*Inputs!$B$31 -> 4080 | F11: =IFERROR(B11*('Rent Roll'!$B$16/Inputs!$B$13)*Inputs!$B$32,0) -> 6136.5625 | G11: =E11-F11 -> -2056.5625
A12: 7 | B12: =IF(A12<Inputs!$B$33,0,MAX(0,MIN(Inputs!$B$45,Inputs!$B$30-SUM($B$5:B11)))) -> 6 | C12: =SUMIFS($B$6:$B$101,$A$6:$A$101,">"&A12,$A$6:$A$101,"<="&A12+Inputs!$B$32) -> 6 | D12: =SUM($B$6:B12) -> 30 | E12: =D12*Inputs!$B$31 -> 5100 | F12: =IFERROR(B12*('Rent Roll'!$B$16/Inputs!$B$13)*Inputs!$B$32,0) -> 6136.5625 | G12: =E12-F12 -> -1036.5625
A13: 8 | B13: =IF(A13<Inputs!$B$33,0,MAX(0,MIN(Inputs!$B$45,Inputs!$B$30-SUM($B$5:B12)))) -> 6 | C13: =SUMIFS($B$6:$B$101,$A$6:$A$101,">"&A13,$A$6:$A$101,"<="&A13+Inputs!$B$32) -> 6 | D13: =SUM($B$6:B13) -> 36 | E13: =D13*Inputs!$B$31 -> 6120 | F13: =IFERROR(B13*('Rent Roll'!$B$16/Inputs!$B$13)*Inputs!$B$32,0) -> 6136.5625 | G13: =E13-F13 -> -16.5625
A14: 9 | B14: =IF(A14<Inputs!$B$33,0,MAX(0,MIN(Inputs!$B$45,Inputs!$B$30-SUM($B$5:B13)))) -> 6 | C14: =SUMIFS($B$6:$B$101,$A$6:$A$101,">"&A14,$A$6:$A$101,"<="&A14+Inputs!$B$32) -> 6 | D14: =SUM($B$6:B14) -> 42 | E14: =D14*Inputs!$B$31 -> 7140 | F14: =IFERROR(B14*('Rent Roll'!$B$16/Inputs!$B$13)*Inputs!$B$32,0) -> 6136.5625 | G14: =E14-F14 -> 1003.4375
A15: 10 | B15: =IF(A15<Inputs!$B$33,0,MAX(0,MIN(Inputs!$B$45,Inputs!$B$30-SUM($B$5:B14)))) -> 6 | C15: =SUMIFS($B$6:$B$101,$A$6:$A$101,">"&A15,$A$6:$A$101,"<="&A15+Inputs!$B$32) -> 6 | D15: =SUM($B$6:B15) -> 48 | E15: =D15*Inputs!$B$31 -> 8160 | F15: =IFERROR(B15*('Rent Roll'!$B$16/Inputs!$B$13)*Inputs!$B$32,0) -> 6136.5625 | G15: =E15-F15 -> 2023.4375
A16: 11 | B16: =IF(A16<Inputs!$B$33,0,MAX(0,MIN(Inputs!$B$45,Inputs!$B$30-SUM($B$5:B15)))) -> 6 | C16: =SUMIFS($B$6:$B$101,$A$6:$A$101,">"&A16,$A$6:$A$101,"<="&A16+Inputs!$B$32) -> 6 | D16: =SUM($B$6:B16) -> 54 | E16: =D16*Inputs!$B$31 -> 9180 | F16: =IFERROR(B16*('Rent Roll'!$B$16/Inputs!$B$13)*Inputs!$B$32,0) -> 6136.5625 | G16: =E16-F16 -> 3043.4375
A17: 12 | B17: =IF(A17<Inputs!$B$33,0,MAX(0,MIN(Inputs!$B$45,Inputs!$B$30-SUM($B$5:B16)))) -> 6 | C17: =SUMIFS($B$6:$B$101,$A$6:$A$101,">"&A17,$A$6:$A$101,"<="&A17+Inputs!$B$32) -> 6 | D17: =SUM($B$6:B17) -> 60 | E17: =D17*Inputs!$B$31 -> 10200 | F17: =IFERROR(B17*('Rent Roll'!$B$16/Inputs!$B$13)*Inputs!$B$32,0) -> 6136.5625 | G17: =E17-F17 -> 4063.4375
... A101: 96 | B101: =IF(A101<Inputs!$B$33,0,MAX(0,MIN(Inputs!$B$45,Inputs!$B$30-SUM($B$5:B100)))) -> 0 | C101: =SUMIFS($B$6:$B$101,$A$6:$A$101,">"&A101,$A$6:$A$101,"<="&A101+Inputs!$B$32) -> 0 | D101: =SUM($B$6:B101) -> 72 | E101: =D101*Inputs!$B$31 -> 12240 | F101: =IFERROR(B101*('Rent Roll'!$B$16/Inputs!$B$13)*Inputs!$B$32,0) -> 0 | G101: =E101-F101 -> 12240
A103: Renovation Schedule Summary - months 1-96 | B103: Net impact | C103: Gross premium | D103: Downtime charged | E103: Units online at year end
A104: Year 1 Net Rent Impact | B104: =SUM(G6:G17) -> -5265.625 | C104: =SUM(E6:E17) -> 56100 | D104: =SUM(F6:F17) -> 61365.625 | E104: =D17 -> 60
A105: Year 2 Net Rent Impact | B105: =SUM(G18:G29) -> 133586.88 | C105: =SUM(E18:E29) -> 145860 | D105: =SUM(F18:F29) -> 12273.125 | E105: =D29 -> 72
A106: Year 3 Net Rent Impact | B106: =SUM(G30:G41) -> 146880 | C106: =SUM(E30:E41) -> 146880 | D106: =SUM(F30:F41) -> 0 | E106: =D41 -> 72
A107: Year 4 Net Rent Impact | B107: =SUM(G42:G53) -> 146880 | C107: =SUM(E42:E53) -> 146880 | D107: =SUM(F42:F53) -> 0 | E107: =D53 -> 72
A108: Year 5 Net Rent Impact | B108: =SUM(G54:G65) -> 146880 | C108: =SUM(E54:E65) -> 146880 | D108: =SUM(F54:F65) -> 0 | E108: =D65 -> 72
A109: Year 6 Net Rent Impact | B109: =SUM(G66:G77) -> 146880 | C109: =SUM(E66:E77) -> 146880 | D109: =SUM(F66:F77) -> 0 | E109: =D77 -> 72
A110: Year 7 Net Rent Impact | B110: =SUM(G78:G89) -> 146880 | C110: =SUM(E78:E89) -> 146880 | D110: =SUM(F78:F89) -> 0 | E110: =D89 -> 72
A111: Year 8 Net Rent Impact | B111: =SUM(G90:G101) -> 146880 | C111: =SUM(E90:E101) -> 146880 | D111: =SUM(F90:F101) -> 0 | E111: =D101 -> 72
A113: Months to complete the programme | B113: =IFERROR(MATCH(Inputs!$B$30,$D$6:$D$101,0),"more than 96") -> 14
A114: Stabilised annual gross premium (reference) | B114: =Inputs!$B$30*Inputs!$B$31*12 -> 146880
A115: Year 1 rent downtime | B115: =SUM(F6:F17) -> 61365.625
A116: Total rent downtime, Years 1-8 | B116: =SUM(F6:F101) -> 73638.75
A118: Each pro forma year now reads its own 12 months from the schedule above, so a slower pace genuinely delays the premium and keeps charging downtime while units are offline. If 'months to complete' exceeds the hold period, the programme never finishes inside the model and the exit NOI reflects that.

Sheet Pro Forma
A1: Eight-Year Pro Forma - Company Underwriting Case
A2: =D30 -> 484834.88 | B2: =K30 -> 843140.9 | C2: =D36 -> 0.043550959 | D2: =E36 -> 0.10061883
A3: YEAR 1 NOI | B3: YEAR 8 NOI | C3: YEAR 1 CASH-ON-CASH | D3: YEAR 2 CASH-ON-CASH
A4: Benchmark column sits at the right, just past Year 8: OUR number in $ per unit per YEAR. Blank = the model uses the T12-based figure. Enter a value and that line switches to benchmark x units from Year 1 on, then grows with expense growth. Turnover is the exception: it is entered on Inputs as $ per TURNED unit and converted here.
A5: Line Item | B5: T12 / Source | C5: T12 $/Unit/Mo | D5: Year 1 | E5: Year 2 | F5: Year 3 | G5: Year 4 | H5: Year 5 | I5: Year 6 | J5: Year 7 | K5: Year 8 | M5: Benchmark ($/Unit/Yr) | N5: Yr-1 $ / Unit | O5: Yr-1 % of EGI
A6: Base Gross Potential Rent | B6: ='T12 Actuals'!$B$6 -> 1305600 | C6: =IFERROR(B6/Units/12,0) -> 1133.3333 | D6: =('Rent Roll'!$B$16*12)+('Rent Roll'!$B$15*12-'Rent Roll'!$B$16*12)*Inputs!$B$44 -> 1243920 | E6: =('Rent Roll'!$B$15*12)*(1+Inputs!$B$21) -> 1348908.6 | F6: =E6*(1+Inputs!$B$21) -> 1389375.9 | G6: =F6*(1+Inputs!$B$21) -> 1431057.1 | H6: =G6*(1+Inputs!$B$21) -> 1473988.8 | I6: =H6*(1+Inputs!$B$21) -> 1518208.5 | J6: =I6*(1+Inputs!$B$21) -> 1563754.8 | K6: =J6*(1+Inputs!$B$21) -> 1610667.4 | N6: =IFERROR($E6/Inputs!$B$13,"") -> 14051.131 | O6: =IFERROR($E6/$E$15,"") -> 0.91570244
A7: Value-Add Rent Impact, Net of Downtime | B7: 0 | C7: =IFERROR(B7/Units/12,0) -> 0 | D7: ='Reno Pace'!$B$104 -> -5265.625 | E7: ='Reno Pace'!$B$105 -> 133586.88 | F7: ='Reno Pace'!$B$106*(1+Inputs!$B$21) -> 151286.4 | G7: ='Reno Pace'!$B$107*(1+Inputs!$B$21)^2 -> 155824.99 | H7: ='Reno Pace'!$B$108*(1+Inputs!$B$21)^3 -> 160499.74 | I7: ='Reno Pace'!$B$109*(1+Inputs!$B$21)^4 -> 165314.73 | J7: ='Reno Pace'!$B$110*(1+Inputs!$B$21)^5 -> 170274.18 | K7: ='Reno Pace'!$B$111*(1+Inputs!$B$21)^6 -> 175382.4 | N7: =IFERROR($E7/Inputs!$B$13,"") -> 1391.5299 | O7: =IFERROR($E7/$E$15,"") -> 0.090685038
A8: Adjusted Gross Potential Rent | B8: =B6+B7 -> 1305600 | C8: =IFERROR(B8/Units/12,0) -> 1133.3333 | D8: =D6+D7 -> 1238654.4 | E8: =E6+E7 -> 1482495.5 | F8: =F6+F7 -> 1540662.3 | G8: =G6+G7 -> 1586882.1 | H8: =H6+H7 -> 1634488.6 | I8: =I6+I7 -> 1683523.2 | J8: =J6+J7 -> 1734028.9 | K8: =K6+K7 -> 1786049.8 | N8: =IFERROR($E8/Inputs!$B$13,"") -> 15442.661 | O8: =IFERROR($E8/$E$15,"") -> 1.0063875
A9: Vacancy % Assumed (1 - stabilized occupancy target) | B9: =Inputs!$B$25 -> 0.0625 | D9: =1-StabilizedOccupancyTarget -> 0.04 | E9: =1-StabilizedOccupancyTarget -> 0.04 | F9: =1-StabilizedOccupancyTarget -> 0.04 | G9: =1-StabilizedOccupancyTarget -> 0.04 | H9: =1-StabilizedOccupancyTarget -> 0.04 | I9: =1-StabilizedOccupancyTarget -> 0.04 | J9: =1-StabilizedOccupancyTarget -> 0.04 | K9: =1-StabilizedOccupancyTarget -> 0.04
A10: Vacancy Loss | B10: ='T12 Actuals'!$B$24 -> -84900 | C10: =IFERROR(B10/Units/12,0) -> -73.697917 | D10: =-D8*D9 -> -49546.175 | E10: =-E8*E9 -> -59299.819 | F10: =-F8*F9 -> -61626.49 | G10: =-G8*G9 -> -63475.285 | H10: =-H8*H9 -> -65379.544 | I10: =-I8*I9 -> -67340.93 | J10: =-J8*J9 -> -69361.158 | K10: =-K8*K9 -> -71441.993 | N10: =IFERROR($E10/Inputs!$B$13,"") -> -617.70645 | O10: =IFERROR($E10/$E$15,"") -> -0.040255499
A11: Bad Debt | B11: ='T12 Actuals'!$B$25 -> -12400 | C11: =IFERROR(B11/Units/12,0) -> -10.763889 | D11: =-D8*Inputs!$B$24 -> -24773.088 | E11: =-E8*Inputs!$B$24 -> -29649.91 | F11: =-F8*Inputs!$B$24 -> -30813.245 | G11: =-G8*Inputs!$B$24 -> -31737.643 | H11: =-H8*Inputs!$B$24 -> -32689.772 | I11: =-I8*Inputs!$B$24 -> -33670.465 | J11: =-J8*Inputs!$B$24 -> -34680.579 | K11: =-K8*Inputs!$B$24 -> -35720.996 | N11: =IFERROR($E11/Inputs!$B$13,"") -> -308.85322 | O11: =IFERROR($E11/$E$15,"") -> -0.02012775
A12: Other Rental Deductions / Concessions | B12: ='T12 Actuals'!$B$26 -> -11800 | C12: =IFERROR(B12/Units/12,0) -> -10.243056 | D12: =-Inputs!$B$29 -> -17433.333 | E12: =D12*(1+Inputs!$B$21) -> -17956.333 | F12: =E12*(1+Inputs!$B$21) -> -18495.023 | G12: =F12*(1+Inputs!$B$21) -> -19049.874 | H12: =G12*(1+Inputs!$B$21) -> -19621.37 | I12: =H12*(1+Inputs!$B$21) -> -20210.011 | J12: =I12*(1+Inputs!$B$21) -> -20816.312 | K12: =J12*(1+Inputs!$B$21) -> -21440.801 | N12: =IFERROR($E12/Inputs!$B$13,"") -> -187.04514 | O12: =IFERROR($E12/$E$15,"") -> -0.012189602
A13: Net Rental Income | B13: ='T12 Actuals'!$B$8 -> 1139100 | C13: =IFERROR(B13/Units/12,0) -> 988.80208 | D13: =SUM(D8:D12) -> 1146901.8 | E13: =SUM(E8:E12) -> 1375589.5 | F13: =SUM(F8:F12) -> 1429727.5 | G13: =SUM(G8:G12) -> 1472619.4 | H13: =SUM(H8:H12) -> 1516797.9 | I13: =SUM(I8:I12) -> 1562301.9 | J13: =SUM(J8:J12) -> 1609170.9 | K13: =SUM(K8:K12) -> 1657446.1 | N13: =IFERROR($E13/Inputs!$B$13,"") -> 14329.057 | O13: =IFERROR($E13/$E$15,"") -> 0.93381466
A14: Other Income | B14: ='T12 Actuals'!$B$9 -> 91900 | C14: =IFERROR(B14/Units/12,0) -> 79.774306 | D14: =(B14+AdditionalOtherIncome)*(1+Inputs!$B$21) -> 94657 | E14: =D14*(1+Inputs!$B$21) -> 97496.71 | F14: =E14*(1+Inputs!$B$21) -> 100421.61 | G14: =F14*(1+Inputs!$B$21) -> 103434.26 | H14: =G14*(1+Inputs!$B$21) -> 106537.29 | I14: =H14*(1+Inputs!$B$21) -> 109733.41 | J14: =I14*(1+Inputs!$B$21) -> 113025.41 | K14: =J14*(1+Inputs!$B$21) -> 116416.17 | N14: =IFERROR($E14/Inputs!$B$13,"") -> 1015.5907 | O14: =IFERROR($E14/$E$15,"") -> 0.066185341
A15: Effective Gross Income | B15: ='T12 Actuals'!$B$10 -> 1231000 | C15: =IFERROR(B15/Units/12,0) -> 1068.5764 | D15: =D13+D14 -> 1241558.8 | E15: =E13+E14 -> 1473086.2 | F15: =F13+F14 -> 1530149.2 | G15: =G13+G14 -> 1576053.6 | H15: =H13+H14 -> 1623335.2 | I15: =I13+I14 -> 1672035.3 | J15: =J13+J14 -> 1722196.3 | K15: =K13+K14 -> 1773862.2 | N15: =IFERROR($E15/Inputs!$B$13,"") -> 15344.648 | O15: =IFERROR($E15/$E$15,"") -> 1
A16: Repairs & Maintenance | B16: ='T12 Actuals'!$B$11 -> 70700 | C16: =IFERROR(B16/Units/12,0) -> 61.371528 | D16: =IF($M16>0,$M16*Units,B16*(1+Inputs!$B$22)) -> 72000 | E16: =D16*(1+Inputs!$B$22) -> 74160 | F16: =E16*(1+Inputs!$B$22) -> 76384.8 | G16: =F16*(1+Inputs!$B$22) -> 78676.344 | H16: =G16*(1+Inputs!$B$22) -> 81036.634 | I16: =H16*(1+Inputs!$B$22) -> 83467.733 | J16: =I16*(1+Inputs!$B$22) -> 85971.765 | K16: =J16*(1+Inputs!$B$22) -> 88550.918 | M16: 750 | N16: =IFERROR($E16/Inputs!$B$13,"") -> 772.5 | O16: =IFERROR($E16/$E$15,"") -> 0.050343287
A17: Turnover Costs | B17: ='T12 Actuals'!$B$12 -> 26600 | C17: =IFERROR(B17/Units/12,0) -> 23.090278 | D17: =IF($M17>0,$M17*Units,B17*(1+Inputs!$B$22)) -> 10560 | E17: =D17*(1+Inputs!$B$22) -> 10876.8 | F17: =E17*(1+Inputs!$B$22) -> 11203.104 | G17: =F17*(1+Inputs!$B$22) -> 11539.197 | H17: =G17*(1+Inputs!$B$22) -> 11885.373 | I17: =H17*(1+Inputs!$B$22) -> 12241.934 | J17: =I17*(1+Inputs!$B$22) -> 12609.192 | K17: =J17*(1+Inputs!$B$22) -> 12987.468 | M17: =Inputs!$B$53*Inputs!$B$50 -> 110 | N17: =IFERROR($E17/Inputs!$B$13,"") -> 113.3 | O17: =IFERROR($E17/$E$15,"") -> 0.0073836821
A18: Labor Costs (Payroll) | B18: ='T12 Actuals'!$B$13 -> 123000 | C18: =IFERROR(B18/Units/12,0) -> 106.77083 | D18: =IF($M18>0,$M18*Units,B18*(1+Inputs!$B$22)) -> 120000 | E18: =D18*(1+Inputs!$B$22) -> 123600 | F18: =E18*(1+Inputs!$B$22) -> 127308 | G18: =F18*(1+Inputs!$B$22) -> 131127.24 | H18: =G18*(1+Inputs!$B$22) -> 135061.06 | I18: =H18*(1+Inputs!$B$22) -> 139112.89 | J18: =I18*(1+Inputs!$B$22) -> 143286.28 | K18: =J18*(1+Inputs!$B$22) -> 147584.86 | M18: 1250 | N18: =IFERROR($E18/Inputs!$B$13,"") -> 1287.5 | O18: =IFERROR($E18/$E$15,"") -> 0.083905479
A19: Advertising & Promotions | B19: ='T12 Actuals'!$B$14 -> 15800 | C19: =IFERROR(B19/Units/12,0) -> 13.715278 | D19: =IF($M19>0,$M19*Units,B19*(1+Inputs!$B$22)) -> 16274 | E19: =D19*(1+Inputs!$B$22) -> 16762.22 | F19: =E19*(1+Inputs!$B$22) -> 17265.087 | G19: =F19*(1+Inputs!$B$22) -> 17783.039 | H19: =G19*(1+Inputs!$B$22) -> 18316.53 | I19: =H19*(1+Inputs!$B$22) -> 18866.026 | J19: =I19*(1+Inputs!$B$22) -> 19432.007 | K19: =J19*(1+Inputs!$B$22) -> 20014.967 | N19: =IFERROR($E19/Inputs!$B$13,"") -> 174.60646 | O19: =IFERROR($E19/$E$15,"") -> 0.011378981
A20: General & Administrative | B20: ='T12 Actuals'!$B$15 -> 27700 | C20: =IFERROR(B20/Units/12,0) -> 24.045139 | D20: =IF($M20>0,$M20*Units,B20*(1+Inputs!$B$22)) -> 28531 | E20: =D20*(1+Inputs!$B$22) -> 29386.93 | F20: =E20*(1+Inputs!$B$22) -> 30268.538 | G20: =F20*(1+Inputs!$B$22) -> 31176.594 | H20: =G20*(1+Inputs!$B$22) -> 32111.892 | I20: =H20*(1+Inputs!$B$22) -> 33075.249 | J20: =I20*(1+Inputs!$B$22) -> 34067.506 | K20: =J20*(1+Inputs!$B$22) -> 35089.531 | N20: =IFERROR($E20/Inputs!$B$13,"") -> 306.11385 | O20: =IFERROR($E20/$E$15,"") -> 0.019949227
A21: Other Controllable (unallocated) | B21: ='T12 Actuals'!$B$16-SUM(B16:B20) -> 0 | C21: =IFERROR(B21/Units/12,0) -> 0 | D21: =B21*(1+Inputs!$B$22) -> 0 | E21: =D21*(1+Inputs!$B$22) -> 0 | F21: =E21*(1+Inputs!$B$22) -> 0 | G21: =F21*(1+Inputs!$B$22) -> 0 | H21: =G21*(1+Inputs!$B$22) -> 0 | I21: =H21*(1+Inputs!$B$22) -> 0 | J21: =I21*(1+Inputs!$B$22) -> 0 | K21: =J21*(1+Inputs!$B$22) -> 0 | N21: =IFERROR($E21/Inputs!$B$13,"") -> 0 | O21: =IFERROR($E21/$E$15,"") -> 0
A22: Utility Costs | B22: ='T12 Actuals'!$B$17 -> 121500 | C22: =IFERROR(B22/Units/12,0) -> 105.46875 | D22: =IF($M22>0,$M22*Units,B22*(1+Inputs!$B$22)) -> 125145 | E22: =D22*(1+Inputs!$B$22) -> 128899.35 | F22: =E22*(1+Inputs!$B$22) -> 132766.33 | G22: =F22*(1+Inputs!$B$22) -> 136749.32 | H22: =G22*(1+Inputs!$B$22) -> 140851.8 | I22: =H22*(1+Inputs!$B$22) -> 145077.35 | J22: =I22*(1+Inputs!$B$22) -> 149429.67 | K22: =J22*(1+Inputs!$B$22) -> 153912.56 | N22: =IFERROR($E22/Inputs!$B$13,"") -> 1342.7016 | O22: =IFERROR($E22/$E$15,"") -> 0.087502926
A23: Insurance and Bonds | B23: ='T12 Actuals'!$B$19 -> 91800 | C23: =IFERROR(B23/Units/12,0) -> 79.6875 | D23: =IF($M23>0,$M23*Units,B23*(1+Inputs!$B$22)) -> 105600 | E23: =D23*(1+Inputs!$B$22) -> 108768 | F23: =E23*(1+Inputs!$B$22) -> 112031.04 | G23: =F23*(1+Inputs!$B$22) -> 115391.97 | H23: =G23*(1+Inputs!$B$22) -> 118853.73 | I23: =H23*(1+Inputs!$B$22) -> 122419.34 | J23: =I23*(1+Inputs!$B$22) -> 126091.92 | K23: =J23*(1+Inputs!$B$22) -> 129874.68 | M23: 1100 | N23: =IFERROR($E23/Inputs!$B$13,"") -> 1133 | O23: =IFERROR($E23/$E$15,"") -> 0.073836821
A24: Property Taxes | B24: ='T12 Actuals'!$B$20 -> 165400 | C24: =IFERROR(B24/Units/12,0) -> 143.57639 | D24: =IF($M24>0,$M24*Units,Tax!$B$22) -> 183876 | E24: =IF($M24>0,D24*(1+Inputs!$B$23),Tax!$C$22) -> 189392.28 | F24: =IF($M24>0,E24*(1+Inputs!$B$23),Tax!$D$22) -> 195074.04 | G24: =IF($M24>0,F24*(1+Inputs!$B$23),Tax!$E$22) -> 200926.27 | H24: =IF($M24>0,G24*(1+Inputs!$B$23),Tax!$F$22) -> 206954.05 | I24: =IF($M24>0,H24*(1+Inputs!$B$23),Tax!$G$22) -> 213162.68 | J24: =IF($M24>0,I24*(1+Inputs!$B$23),Tax!$H$22) -> 219557.56 | K24: =IF($M24>0,J24*(1+Inputs!$B$23),Tax!$I$22) -> 226144.28 | N24: =IFERROR($E24/Inputs!$B$13,"") -> 1972.8362 | O24: =IFERROR($E24/$E$15,"") -> 0.12856836
A25: Other Property Expenses | B25: ='T12 Actuals'!$B$21 -> 22000 | C25: =IFERROR(B25/Units/12,0) -> 19.097222 | D25: =IF($M25>0,$M25*Units,B25*(1+Inputs!$B$22)) -> 22660 | E25: =D25*(1+Inputs!$B$22) -> 23339.8 | F25: =E25*(1+Inputs!$B$22) -> 24039.994 | G25: =F25*(1+Inputs!$B$22) -> 24761.194 | H25: =G25*(1+Inputs!$B$22) -> 25504.03 | I25: =H25*(1+Inputs!$B$22) -> 26269.151 | J25: =I25*(1+Inputs!$B$22) -> 27057.225 | K25: =J25*(1+Inputs!$B$22) -> 27868.942 | N25: =IFERROR($E25/Inputs!$B$13,"") -> 243.12292 | O25: =IFERROR($E25/$E$15,"") -> 0.015844151
A26: Miscellaneous Expense (One-Time, Yr 1) | B26: 0 | C26: =IFERROR(B26/Units/12,0) -> 0 | D26: =Inputs!$B$37 -> 10000 | E26: =0 -> 0 | F26: =0 -> 0 | G26: =0 -> 0 | H26: =0 -> 0 | I26: =0 -> 0 | J26: =0 -> 0 | K26: =0 -> 0 | N26: =IFERROR($E26/Inputs!$B$13,"") -> 0 | O26: =IFERROR($E26/$E$15,"") -> 0
A27: Management Fee | B27: ='T12 Actuals'!$B$18 -> 43085 | C27: =IFERROR(B27/Units/12,0) -> 37.400174 | D27: =IF($M27>0,$M27*Units,D15*Inputs!$B$27) -> 37246.765 | E27: =IF($M27>0,D27*(1+Inputs!$B$22),E15*Inputs!$B$27) -> 44192.585 | F27: =IF($M27>0,E27*(1+Inputs!$B$22),F15*Inputs!$B$27) -> 45904.475 | G27: =IF($M27>0,F27*(1+Inputs!$B$22),G15*Inputs!$B$27) -> 47281.609 | H27: =IF($M27>0,G27*(1+Inputs!$B$22),H15*Inputs!$B$27) -> 48700.057 | I27: =IF($M27>0,H27*(1+Inputs!$B$22),I15*Inputs!$B$27) -> 50161.059 | J27: =IF($M27>0,I27*(1+Inputs!$B$22),J15*Inputs!$B$27) -> 51665.89 | K27: =IF($M27>0,J27*(1+Inputs!$B$22),K15*Inputs!$B$27) -> 53215.867 | N27: =IFERROR($E27/Inputs!$B$13,"") -> 460.33943 | O27: =IFERROR($E27/$E$15,"") -> 0.03
A28: Asset Management Fee | B28: 0 | C28: =IFERROR(B28/Units/12,0) -> 0 | D28: =IF($M28>0,$M28*Units,D15*Inputs!$B$28) -> 24831.176 | E28: =IF($M28>0,D28*(1+Inputs!$B$22),E15*Inputs!$B$28) -> 29461.723 | F28: =IF($M28>0,E28*(1+Inputs!$B$22),F15*Inputs!$B$28) -> 30602.983 | G28: =IF($M28>0,F28*(1+Inputs!$B$22),G15*Inputs!$B$28) -> 31521.072 | H28: =IF($M28>0,G28*(1+Inputs!$B$22),H15*Inputs!$B$28) -> 32466.705 | I28: =IF($M28>0,H28*(1+Inputs!$B$22),I15*Inputs!$B$28) -> 33440.706 | J28: =IF($M28>0,I28*(1+Inputs!$B$22),J15*Inputs!$B$28) -> 34443.927 | K28: =IF($M28>0,J28*(1+Inputs!$B$22),K15*Inputs!$B$28) -> 35477.245 | N28: =IFERROR($E28/Inputs!$B$13,"") -> 306.89295 | O28: =IFERROR($E28/$E$15,"") -> 0.02
A29: Total Operating Expenses | B29: ='T12 Actuals'!$B$22 -> 707585 | C29: =IFERROR(B29/Units/12,0) -> 614.22309 | D29: =SUM(D16:D28) -> 756723.94 | E29: =SUM(E16:E28) -> 778839.68 | F29: =SUM(F16:F28) -> 802848.4 | G29: =SUM(G16:G28) -> 826933.85 | H29: =SUM(H16:H28) -> 851741.86 | I29: =SUM(I16:I28) -> 877294.12 | J29: =SUM(J16:J28) -> 903612.94 | K29: =SUM(K16:K28) -> 930721.33 | N29: =IFERROR($E29/Inputs!$B$13,"") -> 8112.9134 | O29: =IFERROR($E29/$E$15,"") -> 0.52871292
A30: Net Operating Income | B30: ='T12 Actuals'!$B$23 -> 523415 | C30: =IFERROR(B30/Units/12,0) -> 454.3533 | D30: =D15-D29 -> 484834.88 | E30: =E15-E29 -> 694246.48 | F30: =F15-F29 -> 727300.76 | G30: =G15-G29 -> 749119.78 | H30: =H15-H29 -> 771593.37 | I30: =I15-I29 -> 794741.17 | J30: =J15-J29 -> 818583.4 | K30: =K15-K29 -> 843140.9 | N30: =IFERROR($E30/Inputs!$B$13,"") -> 7231.7342 | O30: =IFERROR($E30/$E$15,"") -> 0.47128708
A31: NOI Margin | B31: =IFERROR(B30/B15,0) -> 0.42519496 | D31: =IFERROR(D30/D15,0) -> 0.39050496 | E31: =IFERROR(E30/E15,0) -> 0.47128708 | F31: =IFERROR(F30/F15,0) -> 0.47531364 | G31: =IFERROR(G30/G15,0) -> 0.47531364 | H31: =IFERROR(H30/H15,0) -> 0.47531363 | I31: =IFERROR(I30/I15,0) -> 0.47531363 | J31: =IFERROR(J30/J15,0) -> 0.47531363 | K31: =IFERROR(K30/K15,0) -> 0.47531363
A33: FINANCING & CASH FLOW
A34: Annual Mortgage Payment (Debt Service) | D34: ='Debt & Exit'!$B$17 -> 325023.83 | E34: ='Debt & Exit'!$B$17 -> 325023.83 | F34: ='Debt & Exit'!$B$17 -> 325023.83 | G34: ='Debt & Exit'!$B$17 -> 325023.83 | H34: ='Debt & Exit'!$B$17 -> 325023.83 | I34: ='Debt & Exit'!$B$17 -> 325023.83 | J34: ='Debt & Exit'!$B$17 -> 325023.83 | K34: ='Debt & Exit'!$B$17 -> 325023.83
A35: Net Income After Debt Service | D35: =D30-D34 -> 159811.05 | E35: =E30-E34 -> 369222.65 | F35: =F30-F34 -> 402276.92 | G35: =G30-G34 -> 424095.95 | H35: =H30-H34 -> 446569.54 | I35: =I30-I34 -> 469717.34 | J35: =J30-J34 -> 493559.57 | K35: =K30-K34 -> 518117.07
A36: Cash-on-Cash Return % | D36: =D35/'Debt & Exit'!$B$12 -> 0.043550959 | E36: =E35/'Debt & Exit'!$B$12 -> 0.10061883 | F36: =F35/'Debt & Exit'!$B$12 -> 0.10962662 | G36: =G35/'Debt & Exit'!$B$12 -> 0.11557264 | H36: =H35/'Debt & Exit'!$B$12 -> 0.12169704 | I36: =I35/'Debt & Exit'!$B$12 -> 0.12800517 | J36: =J35/'Debt & Exit'!$B$12 -> 0.13450254 | K36: =K35/'Debt & Exit'!$B$12 -> 0.14119484
A37: Replacement Reserves (below the line) | D37: =Inputs!$B$54*Units -> 24000 | E37: =D37*(1+Inputs!$B$22) -> 24720 | F37: =E37*(1+Inputs!$B$22) -> 25461.6 | G37: =F37*(1+Inputs!$B$22) -> 26225.448 | H37: =G37*(1+Inputs!$B$22) -> 27012.211 | I37: =H37*(1+Inputs!$B$22) -> 27822.578 | J37: =I37*(1+Inputs!$B$22) -> 28657.255 | K37: =J37*(1+Inputs!$B$22) -> 29516.973
A38: Net Cash Flow After Reserves | D38: =D35-D37 -> 135811.05 | E38: =E35-E37 -> 344502.65 | F38: =F35-F37 -> 376815.32 | G38: =G35-G37 -> 397870.5 | H38: =H35-H37 -> 419557.33 | I38: =I35-I37 -> 441894.76 | J38: =J35-J37 -> 464902.32 | K38: =K35-K37 -> 488600.1
A39: Cash-on-Cash After Reserves % | D39: =D38/'Debt & Exit'!$B$12 -> 0.037010591 | E39: =E38/'Debt & Exit'!$B$12 -> 0.093882247 | F39: =F38/'Debt & Exit'!$B$12 -> 0.10268795 | G39: =G38/'Debt & Exit'!$B$12 -> 0.1084258 | H39: =H38/'Debt & Exit'!$B$12 -> 0.1143358 | I39: =I38/'Debt & Exit'!$B$12 -> 0.12042309 | J39: =J38/'Debt & Exit'!$B$12 -> 0.126693 | K39: =K38/'Debt & Exit'!$B$12 -> 0.13315101
A41: Reserves sit below NOI on purpose. NOI is what the purchase cap rate, the exit cap rate and every scenario value are applied to, so charging reserves into operating expenses would quietly change the price of the deal. The lines above show what the reserve costs in cash without touching that.

Sheet Debt & Exit
A1: Debt, Exit, and Returns
A2: =B6 -> 8442177.4 | B2: =B8 -> 5909524.2 | C2: =B25 -> 0.19043256 | D2: =B26 -> 2.2099212
A3: PURCHASE PRICE | B3: LOAN AMOUNT | C3: ="LEVERED IRR ("&Inputs!$B$17&"-YR)" -> LEVERED IRR (5-YR) | D3: EQUITY MULTIPLE
A5: Metric | B5: Amount | C5: Notes
A6: Purchase Price | B6: =IF(Inputs!$B$6>0,Inputs!$B$6,'T12 Actuals'!$B$23/Inputs!$B$14) -> 8442177.4 | C6: T12 NOI / purchase cap, unless a manual override price is entered on Inputs (B30). price from actual T12 NOI.
A7: Price Per Unit | B7: =IFERROR(B6/Inputs!$B$13,0) -> 87939.348 | C7: Purchase price / units. Market pricing check.
A8: Loan Amount | B8: =B6*Inputs!$B$15 -> 5909524.2 | C8: Purchase price x 70% LTV. Debt sizing.
A9: Equity Before Capex | B9: =B6-B8 -> 2532653.2 | C9: Purchase price - loan amount. Base equity need.
A10: Total Capex | B10: =Inputs!$B$36 -> 883600 | C10: Linked to Inputs total capex. Renovation/common budget.
A11: Upfront Acquisition Closing Cost | B11: =B6*Inputs!$B$20 -> 253265.32 | C11: Purchase price x 3%. Upfront acquisition closing cost.
A12: Initial Equity Required | B12: =B6+B10+B11-B8 -> 3669518.5 | C12: Purchase price + capex + upfront closing cost - loan. Used as Year 0 cash outflow.
A13: Gross Exit Value | B13: =INDEX('Pro Forma'!$D$30:$K$30,Inputs!$B$17)/Inputs!$B$18 -> 12859889 | C13: The hold-period year's NOI / exit cap rate. Change Hold Period on Inputs and the sale moves with it. Sale proceeds before costs.
A14: Disposition Cost at Exit | B14: =B13*Inputs!$B$19 -> 642994.47 | C14: Gross exit value x 5%. Closing cost subtracted at exit.
A15: Loan Payoff | B15: =$B$18 -> 5909524.2 | C15: Loan balance at the end of the hold period; equals the original loan when interest-only.
A16: Net Sale Proceeds | B16: =B13-B14-B15 -> 6307370.8 | C16: Gross exit value - disposition cost - loan payoff. Cash received at sale before final year cash flow.
A17: Annual Debt Service (computed) | B17: =IF(Inputs!$B$46=0,$B$8*Inputs!$B$16,-PMT(Inputs!$B$16,Inputs!$B$46,$B$8)) -> 325023.83 | C17: FIX #6: interest-only if amortization=0, else amortizing payment.
A18: =CONCATENATE("Acq Loan Balance @ Exit (Yr ",Inputs!$B$17,")") -> Acq Loan Balance @ Exit (Yr 5) | B18: =$B$8*(1+Inputs!$B$16)^Inputs!$B$17-$B$17*((1+Inputs!$B$16)^Inputs!$B$17-1)/Inputs!$B$16 -> 5909524.2 | C18: Remaining principal at sale; equals full loan when interest-only.
A19: Metric | B19: Year 0 | C19: Year 1 | D19: Year 2 | E19: Year 3 | F19: Year 4 | G19: Year 5 | H19: Year 6 | I19: Year 7 | J19: Year 8 | K19: How/Why
A20: NOI | C20: ='Pro Forma'!$D$30 -> 484834.88 | D20: ='Pro Forma'!$E$30 -> 694246.48 | E20: ='Pro Forma'!$F$30 -> 727300.76 | F20: ='Pro Forma'!$G$30 -> 749119.78 | G20: ='Pro Forma'!$H$30 -> 771593.37 | H20: ='Pro Forma'!$I$30 -> 794741.17 | I20: ='Pro Forma'!$J$30 -> 818583.4 | J20: ='Pro Forma'!$K$30 -> 843140.9 | K20: Linked from the Pro Forma, Years 1-8.
A21: Debt Service | C21: =IF(Inputs!$B$17>=1,$B$17,0) -> 325023.83 | D21: =IF(Inputs!$B$17>=2,$B$17,0) -> 325023.83 | E21: =IF(Inputs!$B$17>=3,$B$17,0) -> 325023.83 | F21: =IF(Inputs!$B$17>=4,$B$17,0) -> 325023.83 | G21: =IF(Inputs!$B$17>=5,$B$17,0) -> 325023.83 | H21: =IF(Inputs!$B$17>=6,$B$17,0) -> 0 | I21: =IF(Inputs!$B$17>=7,$B$17,0) -> 0 | J21: =IF(Inputs!$B$17>=8,$B$17,0) -> 0 | K21: Acquisition debt service; zero once the hold period is over.
